Workbook

Sheet Cocina C
G2: ANEXO No. 1.
G3: TABLA 1A
G4: Cumplimiento del plan de consumo de energía eléctrica total, mes: | N4: 45658
C5: SERVICIO: COCINA COMEDOR | U5: total | V5: diaria
N6: Plan Pico N | O6: =S6*16.5% -> 3795 | P6: Plan Pico D | Q6: =(S6*8)/100 -> 1840 | R6: PLAN MES | S6: 23000 | T6: Perdidas: | U6: 481 | V6: =U6/31 -> 15.516129
B7: Día | C7: Lectura del contador | J7: Consumo diario kWh y kvarh | N7: Consumo diario Pico nocturno kWh | Q7: Consumo diario pico Diurno kWh | R7: Consumo diario total kWh | U7: Consumo acumulado Pico kWh | X7: Consumo acumulado Total kWh | AB7: Firma Responsable
C8: MAD | D8: DIA | E8: PICO | F8: TOTAL | G8: Pico Diurno 11 am | H8: Pico Diurno 1 pm | I8: REACT | J8: MAD | K8: DIA | L8: PICO | M8: REACT | N8: Plan Pico | O8: Real Pico | P8: Plan - Real | R8: Plan | S8: Real | T8: Plan - Real | U8: Plan Pico | V8: Real Pico | W8: Plan - Real | X8: Plan | Y8: Real | Z8: Plan - Real | AA8: FP
C9: 1 | D9: 2 | E9: 3 | G9: 4 | H9: 5 | I9: 6 | J9: 7 | K9: 8 | L9: 9 | M9: 10 | N9: 11 | O9: 12 | P9: 13 | Q9: 14 | R9: 15 | S9: 16 | T9: 17 | U9: 18 | V9: 19 | W9: 20 | X9: 21 | Y9: 22 | Z9: 23 | AA9: 24 | AB9: 25
B11: 31 | C11: 283661 | D11: 598092 | E11: 145089 | F11: =C11+D11+E11 -> 1026842 | G11: =(C12+D12+E12)+((S11/24)*9.5) -> 1026620.9 | H11: =G11+((K11/12)*2.5) -> 1026635.2 | I11: 718566 | J11: =C11-C12 -> 282 | K11: =D11-D12 -> 69 | L11: =E11-E12 -> 15 | M11: =I11-I12 -> 288 | N11: =N12 -> 122.41935 | O11: =L11 -> 15 | P11: =N11-O11 -> 107.41935 | Q11: =H11-G11 -> 14.375 | R11: =R12 -> 741.93548 | S11: =J11+K11+L11 -> 366 | T11: =R11-S11 -> 375.93548 | U11: =U12+N11 -> 3795 | V11: =V12+O11 -> 2097 | W11: =U11-V11 -> 1698 | X11: =X12+R11 -> 23000 | Y11: =Y12+S11 -> 15343.516 | Z11: =X11-Y11 -> 7656.4839 | AA11: =COS(ATAN(M11/S11)) -> 0.78587108
B12: 30 | C12: =C13+214 -> 283379 | D12: =D13+114 -> 598023 | E12: =E13+10 -> 145074 | F12: =C12+D12+E12 -> 1026476 | G12: =(C13+D13+E13)+((S12/24)*7.5) -> 1026243.6 | H12: =G12+((K12/12)*2.5) -> 1026267.4 | I12: =I13+212 -> 718278 | J12: =C12-C13 -> 214 | K12: =D12-D13 -> 114 | L12: =E12-E13 -> 10 | M12: =I12-I13 -> 212 | N12: =N13 -> 122.41935 | O12: =L12 -> 10 | P12: =N12-O12 -> 112.41935 | Q12: =H12-G12 -> 23.75 | R12: =R13 -> 741.93548 | S12: =J12+K12+L12 -> 338 | T12: =R12-S12 -> 403.93548 | U12: =U13+N12 -> 3672.5806 | V12: =V13+O12 -> 2082 | W12: =U12-V12 -> 1590.5806 | X12: =X13+R12 -> 22258.065 | Y12: =Y13+S12 -> 14977.516 | Z12: =X12-Y12 -> 7280.5484 | AA12: =COS(ATAN(M12/S12)) -> 0.84715238
B13: 29 | C13: =C14+210 -> 283165 | D13: =D14+190 -> 597909 | E13: =E14+8 -> 145064 | F13: =C13+D13+E13 -> 1026138 | G13: =(C14+D14+E14)+((S13/24)*7.5) -> 1025857.5 | H13: =G13+((K13/12)*2.5) -> 1025897.1 | I13: =I14+209 -> 718066 | J13: =C13-C14 -> 210 | K13: =D13-D14 -> 190 | L13: =E13-E14 -> 8 | M13: =I13-I14 -> 209 | N13: =N14 -> 122.41935 | O13: =L13 -> 8 | P13: =N13-O13 -> 114.41935 | Q13: =H13-G13 -> 39.583333 | R13: =R14 -> 741.93548 | S13: =J13+K13+L13 -> 408 | T13: =R13-S13 -> 333.93548 | U13: =U14+N13 -> 3550.1613 | V13: =V14+O13 -> 2072 | W13: =U13-V13 -> 1478.1613 | X13: =X14+R13 -> 21516.129 | Y13: =Y14+S13 -> 14639.516 | Z13: =X13-Y13 -> 6876.6129 | AA13: =COS(ATAN(M13/S13)) -> 0.89002178
B14: 28 | C14: 282955 | D14: 597719 | E14: =144997+59 -> 145056 | F14: =C14+D14+E14 -> 1025730 | G14: =(C15+D15+E15)+((S14/24)*7.5) -> 1025404.8 | H14: =G14+((K14/12)*2.5) -> 1025451.1 | I14: 717857 | J14: =C14-C15 -> 186 | K14: =D14-D15 -> 222 | L14: =E14-E15 -> 65 | M14: =I14-I15 -> 294 | N14: =N15 -> 122.41935 | O14: =L14 -> 65 | P14: =N14-O14 -> 57.419355 | Q14: =H14-G14 -> 46.25 | R14: =R15 -> 741.93548 | S14: =J14+K14+L14 -> 473 | T14: =R14-S14 -> 268.93548 | U14: =U15+N14 -> 3427.7419 | V14: =V15+O14 -> 2064 | W14: =U14-V14 -> 1363.7419 | X14: =X15+R14 -> 20774.194 | Y14: =Y15+S14 -> 14231.516 | Z14: =X14-Y14 -> 6542.6774 | AA14: =COS(ATAN(M14/S14)) -> 0.84930708
B15: 27 | C15: =C16+184 -> 282769 | D15: =D16+220 -> 597497 | E15: =E16+69 -> 144991 | F15: =C15+D15+E15 -> 1025257 | G15: =(C16+D16+E16)+((S15/24)*7.5) -> 1024931.8 | H15: =G15+((K15/12)*2.5) -> 1024977.6 | I15: =I16+296 -> 717563 | J15: =C15-C16 -> 184 | K15: =D15-D16 -> 220 | L15: =E15-E16 -> 69 | M15: =I15-I16 -> 296 | N15: =N16 -> 122.41935 | O15: =L15 -> 69 | P15: =N15-O15 -> 53.419355 | Q15: =H15-G15 -> 45.833333 | R15: =R16 -> 741.93548 | S15: =J15+K15+L15 -> 473 | T15: =R15-S15 -> 268.93548 | U15: =U16+N15 -> 3305.3226 | V15: =V16+O15 -> 1999 | W15: =U15-V15 -> 1306.3226 | X15: =X16+R15 -> 20032.258 | Y15: =Y16+S15 -> 13758.516 | Z15: =X15-Y15 -> 6273.7419 | AA15: =COS(ATAN(M15/S15)) -> 0.84769612
B16: 26 | C16: =C17+191 -> 282585 | D16: =D17+228 -> 597277 | E16: =E17+64 -> 144922 | F16: =C16+D16+E16 -> 1024784 | G16: =(C17+D17+E17)+((S16/24)*7.5) -> 1024451.9 | H16: =G16+((K16/12)*2.5) -> 1024499.4 | I16: =I17+290 -> 717267 | J16: =C16-C17 -> 191 | K16: =D16-D17 -> 228 | L16: =E16-E17 -> 64 | M16: =I16-I17 -> 290 | N16: =N17 -> 122.41935 | O16: =L16 -> 64 | P16: =N16-O16 -> 58.419355 | Q16: =H16-G16 -> 47.5 | R16: =R17 -> 741.93548 | S16: =J16+K16+L16 -> 483 | T16: =R16-S16 -> 258.93548 | U16: =U17+N16 -> 3182.9032 | V16: =V17+O16 -> 1930 | W16: =U16-V16 -> 1252.9032 | X16: =X17+R16 -> 19290.323 | Y16: =Y17+S16 -> 13285.516 | Z16: =X16-Y16 -> 6004.8065 | AA16: =COS(ATAN(M16/S16)) -> 0.85733627
B17: 25 | C17: =C18+189 -> 282394 | D17: =D18+222 -> 597049 | E17: =E18+52 -> 144858 | F17: =C17+D17+E17 -> 1024301 | G17: =(C18+D18+E18)+((S17/24)*7.5) -> 1023982.7 | H17: =G17+((K17/12)*2.5) -> 1024028.9 | I17: =I18+295 -> 716977 | J17: =C17-C18 -> 189 | K17: =D17-D18 -> 222 | L17: =E17-E18 -> 52 | M17: =I17-I18 -> 295 | N17: =N18 -> 122.41935 | O17: =L17 -> 52 | P17: =N17-O17 -> 70.419355 | Q17: =H17-G17 -> 46.25 | R17: =R18 -> 741.93548 | S17: =J17+K17+L17 -> 463 | T17: =R17-S17 -> 278.93548 | U17: =U18+N17 -> 3060.4839 | V17: =V18+O17 -> 1866 | W17: =U17-V17 -> 1194.4839 | X17: =X18+R17 -> 18548.387 | Y17: =Y18+S17 -> 12802.516 | Z17: =X17-Y17 -> 5745.871 | AA17: =COS(ATAN(M17/S17)) -> 0.84336134
B18: 24 | C18: =C19+185 -> 282205 | D18: =D19+219 -> 596827 | E18: =E19+59 -> 144806 | F18: =C18+D18+E18 -> 1023838 | G18: =(C19+D19+E19)+((S18/24)*7.5) -> 1023519.7 | H18: =G18+((K18/12)*2.5) -> 1023565.3 | I18: =I19+291 -> 716682 | J18: =C18-C19 -> 185 | K18: =D18-D19 -> 219 | L18: =E18-E19 -> 59 | M18: =I18-I19 -> 291 | N18: =N19 -> 122.41935 | O18: =L18 -> 59 | P18: =N18-O18 -> 63.419355 | Q18: =H18-G18 -> 45.625 | R18: =R19 -> 741.93548 | S18: =J18+K18+L18 -> 463 | T18: =R18-S18 -> 278.93548 | U18: =U19+N18 -> 2938.0645 | V18: =V19+O18 -> 1814 | W18: =U18-V18 -> 1124.0645 | X18: =X19+R18 -> 17806.452 | Y18: =Y19+S18 -> 12339.516 | Z18: =X18-Y18 -> 5466.9355 | AA18: =COS(ATAN(M18/S18)) -> 0.84666009
B19: 23 | C19: =C20+187 -> 282020 | D19: =D20+210 -> 596608 | E19: =E20+62 -> 144747 | F19: =C19+D19+E19 -> 1023375 | G19: =(C20+D20+E20)+((S19/24)*7.5) -> 1023059.4 | H19: =G19+((K19/12)*2.5) -> 1023103.2 | I19: =I20+293 -> 716391 | J19: =C19-C20 -> 187 | K19: =D19-D20 -> 210 | L19: =E19-E20 -> 62 | M19: =I19-I20 -> 293 | N19: =N20 -> 122.41935 | O19: =L19 -> 62 | P19: =N19-O19 -> 60.419355 | Q19: =H19-G19 -> 43.75 | R19: =R20 -> 741.93548 | S19: =J19+K19+L19 -> 459 | T19: =R19-S19 -> 282.93548 | U19: =U20+N19 -> 2815.6452 | V19: =V20+O19 -> 1755 | W19: =U19-V19 -> 1060.6452 | X19: =X20+R19 -> 17064.516 | Y19: =Y20+S19 -> 11876.516 | Z19: =X19-Y19 -> 5188 | AA19: =COS(ATAN(M19/S19)) -> 0.84290449
B20: 22 | C20: 281833 | D20: 596398 | E20: 144685 | F20: =C20+D20+E20 -> 1022916 | G20: =(C21+D21+E21)+((S20/24)*7.5) -> 1022592.2 | H20: =G20+((K20/12)*2.5) -> 1022635.1 | I20: 716098 | J20: =C20-C21 -> 190 | K20: =D20-D21 -> 206 | L20: =E20-E21 -> 75 | M20: =I20-I21 -> 310 | N20: =N21 -> 122.41935 | O20: =L20 -> 75 | P20: =N20-O20 -> 47.419355 | Q20: =H20-G20 -> 42.916667 | R20: =R21 -> 741.93548 | S20: =J20+K20+L20 -> 471 | T20: =R20-S20 -> 270.93548 | U20: =U21+N20 -> 2693.2258 | V20: =V21+O20 -> 1693 | W20: =U20-V20 -> 1000.2258 | X20: =X21+R20 -> 16322.581 | Y20: =Y21+S20 -> 11417.516 | Z20: =X20-Y20 -> 4905.0645 | AA20: =COS(ATAN(M20/S20)) -> 0.83530992
B21: 21 | C21: =C22+191 -> 281643 | D21: =D22+213 -> 596192 | E21: =E22+70 -> 144610 | F21: =C21+D21+E21 -> 1022445 | G21: =(C22+D22+E22)+((S21/24)*7.5) -> 1022119.1 | H21: =G21+((K21/12)*2.5) -> 1022163.5 | I21: =I22+290 -> 715788 | J21: =C21-C22 -> 191 | K21: =D21-D22 -> 213 | L21: =E21-E22 -> 70 | M21: =I21-I22 -> 290 | N21: =N22 -> 122.41935 | O21: =L21 -> 70 | P21: =N21-O21 -> 52.419355 | Q21: =H21-G21 -> 44.375 | R21: =R22 -> 741.93548 | S21: =J21+K21+L21 -> 474 | T21: =R21-S21 -> 267.93548 | U21: =U22+N21 -> 2570.8065 | V21: =V22+O21 -> 1618 | W21: =U21-V21 -> 952.80645 | X21: =X22+R21 -> 15580.645 | Y21: =Y22+S21 -> 10946.516 | Z21: =X21-Y21 -> 4634.129 | AA21: =COS(ATAN(M21/S21)) -> 0.85301481
B22: 20 | C22: =C23+193 -> 281452 | D22: =D23+214 -> 595979 | E22: =E23+62 -> 144540 | F22: =C22+D22+E22 -> 1021971 | G22: =(C23+D23+E23)+((S22/24)*7.5) -> 1021648.6 | H22: =G22+((K22/12)*2.5) -> 1021693.1 | I22: =I23+304 -> 715498 | J22: =C22-C23 -> 193 | K22: =D22-D23 -> 214 | L22: =E22-E23 -> 62 | M22: =I22-I23 -> 304 | N22: =N23 -> 122.41935 | O22: =L22 -> 62 | P22: =N22-O22 -> 60.419355 | Q22: =H22-G22 -> 44.583333 | R22: =R23 -> 741.93548 | S22: =J22+K22+L22 -> 469 | T22: =R22-S22 -> 272.93548 | U22: =U23+N22 -> 2448.3871 | V22: =V23+O22 -> 1548 | W22: =U22-V22 -> 900.3871 | X22: =X23+R22 -> 14838.71 | Y22: =Y23+S22 -> 10472.516 | Z22: =X22-Y22 -> 4366.1935 | AA22: =COS(ATAN(M22/S22)) -> 0.83913786
B23: 19 | C23: =C24+197 -> 281259 | D23: =D24+211 -> 595765 | E23: =E24+71 -> 144478 | F23: =C23+D23+E23 -> 1021502 | G23: =(C24+D24+E24)+((S23/24)*7.5) -> 1021172.7 | H23: =G23+((K23/12)*2.5) -> 1021216.6 | I23: =I24+302 -> 715194 | J23: =C23-C24 -> 197 | K23: =D23-D24 -> 211 | L23: =E23-E24 -> 71 | M23: =I23-I24 -> 302 | N23: =N24 -> 122.41935 | O23: =L23 -> 71 | P23: =N23-O23 -> 51.419355 | Q23: =H23-G23 -> 43.958333 | R23: =R24 -> 741.93548 | S23: =J23+K23+L23 -> 479 | T23: =R23-S23 -> 262.93548 | U23: =U24+N23 -> 2325.9677 | V23: =V24+O23 -> 1486 | W23: =U23-V23 -> 839.96774 | X23: =X24+R23 -> 14096.774 | Y23: =Y24+S23 -> 10003.516 | Z23: =X23-Y23 -> 4093.2581 | AA23: =COS(ATAN(M23/S23)) -> 0.84590828
B24: 18 | C24: =C25+190 -> 281062 | D24: =D25+210 -> 595554 | E24: =E25+67 -> 144407 | F24: =C24+D24+E24 -> 1021023 | G24: =(C25+D25+E25)+((S24/24)*7.5) -> 1020701.9 | H24: =G24+((K24/12)*2.5) -> 1020745.7 | I24: =I25+307 -> 714892 | J24: =C24-C25 -> 190 | K24: =D24-D25 -> 210 | L24: =E24-E25 -> 67 | M24: =I24-I25 -> 307 | N24: =N25 -> 122.41935 | O24: =L24 -> 67 | P24: =N24-O24 -> 55.419355 | Q24: =H24-G24 -> 43.75 | R24: =R25 -> 741.93548 | S24: =J24+K24+L24 -> 467 | T24: =R24-S24 -> 274.93548 | U24: =U25+N24 -> 2203.5484 | V24: =V25+O24 -> 1415 | W24: =U24-V24 -> 788.54839 | X24: =X25+R24 -> 13354.839 | Y24: =Y25+S24 -> 9524.5161 | Z24: =X24-Y24 -> 3830.3226 | AA24: =COS(ATAN(M24/S24)) -> 0.83561162
B25: 17 | C25: =C26+194 -> 280872 | D25: =D26+212 -> 595344 | E25: =E26+69 -> 144340 | F25: =C25+D25+E25 -> 1020556 | G25: =(C26+D26+E26)+((S25/24)*7.5) -> 1020229.4 | H25: =G25+((K25/12)*2.5) -> 1020273.6 | I25: =I26+301 -> 714585 | J25: =C25-C26 -> 194 | K25: =D25-D26 -> 212 | L25: =E25-E26 -> 69 | M25: =I25-I26 -> 301 | N25: =N26 -> 122.41935 | O25: =L25 -> 69 | P25: =N25-O25 -> 53.419355 | Q25: =H25-G25 -> 44.166667 | R25: =R26 -> 741.93548 | S25: =J25+K25+L25 -> 475 | T25: =R25-S25 -> 266.93548 | U25: =U26+N25 -> 2081.129 | V25: =V26+O25 -> 1348 | W25: =U25-V25 -> 733.12903 | X25: =X26+R25 -> 12612.903 | Y25: =Y26+S25 -> 9057.5161 | Z25: =X25-Y25 -> 3555.3871 | AA25: =COS(ATAN(M25/S25)) -> 0.84468508
B26: 16 | C26: =C27+198 -> 280678 | D26: =D27+215 -> 595132 | E26: =E27+71 -> 144271 | F26: =C26+D26+E26 -> 1020081 | G26: =(C27+D27+E27)+((S26/24)*7.5) -> 1019748.2 | H26: =G26+((K26/12)*2.5) -> 1019793 | I26: =I27+304 -> 714284 | J26: =C26-C27 -> 198 | K26: =D26-D27 -> 215 | L26: =E26-E27 -> 71 | M26: =I26-I27 -> 304 | N26: =N27 -> 122.41935 | O26: =L26 -> 71 | P26: =N26-O26 -> 51.419355 | Q26: =H26-G26 -> 44.791667 | R26: =R27 -> 741.93548 | S26: =J26+K26+L26 -> 484 | T26: =R26-S26 -> 257.93548 | U26: =U27+N26 -> 1958.7097 | V26: =V27+O26 -> 1279 | W26: =U26-V26 -> 679.70968 | X26: =X27+R26 -> 11870.968 | Y26: =Y27+S26 -> 8582.5161 | Z26: =X26-Y26 -> 3288.4516 | AA26: =COS(ATAN(M26/S26)) -> 0.84681668
B27: 15 | C27: =C28+201 -> 280480 | D27: =D28+218 -> 594917 | E27: =E28+73 -> 144200 | F27: =C27+D27+E27 -> 1019597 | G27: =(C28+D28+E28)+((S27/24)*7.5) -> 1019258.8 | H27: =G27+((K27/12)*2.5) -> 1019304.2 | I27: =I28+314 -> 713980 | J27: =C27-C28 -> 201 | K27: =D27-D28 -> 218 | L27: =E27-E28 -> 73 | M27: =I27-I28 -> 314 | N27: =N28 -> 122.41935 | O27: =L27 -> 73 | P27: =N27-O27 -> 49.419355 | Q27: =H27-G27 -> 45.416667 | R27: =R28 -> 741.93548 | S27: =J27+K27+L27 -> 492 | T27: =R27-S27 -> 249.93548 | U27: =U28+N27 -> 1836.2903 | V27: =V28+O27 -> 1208 | W27: =U27-V27 -> 628.29032 | X27: =X28+R27 -> 11129.032 | Y27: =Y28+S27 -> 8098.5161 | Z27: =X27-Y27 -> 3030.5161 | AA27: =COS(ATAN(M27/S27)) -> 0.84295527
B28: 14 | C28: =C29+213 -> 280279 | D28: =D29+327 -> 594699 | E28: =E29+92 -> 144127 | F28: =C28+D28+E28 -> 1019105 | G28: =(C29+D29+E29)+((S28/24)*7.5) -> 1018670.5 | H28: =G28+((K28/12)*2.5) -> 1018738.6 | I28: =I29+385 -> 713666 | J28: =C28-C29 -> 213 | K28: =D28-D29 -> 327 | L28: =E28-E29 -> 92 | M28: =I28-I29 -> 385 | N28: =N29 -> 122.41935 | O28: =L28 -> 92 | P28: =N28-O28 -> 30.419355 | Q28: =H28-G28 -> 68.125 | R28: =R29 -> 741.93548 | S28: =J28+K28+L28 -> 632 | T28: =R28-S28 -> 109.93548 | U28: =U29+N28 -> 1713.871 | V28: =V29+O28 -> 1135 | W28: =U28-V28 -> 578.87097 | X28: =X29+R28 -> 10387.097 | Y28: =Y29+S28 -> 7606.5161 | Z28: =X28-Y28 -> 2780.5806 | AA28: =COS(ATAN(M28/S28)) -> 0.85401585
B29: 13 | C29: 280066 | D29: 594372 | E29: 144035 | F29: =C29+D29+E29 -> 1018473 | G29: =(C30+D30+E30)+((S29/24)*7.5) -> 1018027.5 | H29: =G29+((K29/12)*2.5) -> 1018099.4 | I29: 713281 | J29: =C29-C30 -> 209 | K29: =D29-D30 -> 345 | L29: =E29-E30 -> 94 | M29: =I29-I30 -> 381 | N29: =N30 -> 122.41935 | O29: =L29 -> 94 | P29: =N29-O29 -> 28.419355 | Q29: =H29-G29 -> 71.875 | R29: =R30 -> 741.93548 | S29: =J29+K29+L29 -> 648 | T29: =R29-S29 -> 93.935484 | U29: =U30+N29 -> 1591.4516 | V29: =V30+O29 -> 1043 | W29: =U29-V29 -> 548.45161 | X29: =X30+R29 -> 9645.1613 | Y29: =Y30+S29 -> 6974.5161 | Z29: =X29-Y29 -> 2670.6452 | AA29: =COS(ATAN(M29/S29)) -> 0.86203679
B30: 12 | C30: =C31+207 -> 279857 | D30: =D31+333 -> 594027 | E30: =E31+91 -> 143941 | F30: =C30+D30+E30 -> 1017825 | G30: =(C31+D31+E31)+((S30/24)*7.5) -> 1017391.2 | H30: =G30+((K30/12)*2.5) -> 1017460.6 | I30: =I31+397 -> 712900 | J30: =C30-C31 -> 207 | K30: =D30-D31 -> 333 | L30: =E30-E31 -> 91 | M30: =I30-I31 -> 397 | N30: =N31 -> 122.41935 | O30: =L30 -> 91 | P30: =N30-O30 -> 31.419355 | Q30: =H30-G30 -> 69.375 | R30: =R31 -> 741.93548 | S30: =J30+K30+L30 -> 631 | T30: =R30-S30 -> 110.93548 | U30: =U31+N30 -> 1469.0323 | V30: =V31+O30 -> 949 | W30: =U30-V30 -> 520.03226 | X30: =X31+R30 -> 8903.2258 | Y30: =Y31+S30 -> 6326.5161 | Z30: =X30-Y30 -> 2576.7097 | AA30: =COS(ATAN(M30/S30)) -> 0.84641199
B31: 11 | C31: =C32+203 -> 279650 | D31: =D32+323 -> 593694 | E31: =E32+95 -> 143850 | F31: =C31+D31+E31 -> 1017194 | G31: =(C32+D32+E32)+((S31/24)*7.5) -> 1016767.1 | H31: =G31+((K31/12)*2.5) -> 1016834.4 | I31: =I32+392 -> 712503 | J31: =C31-C32 -> 203 | K31: =D31-D32 -> 323 | L31: =E31-E32 -> 95 | M31: =I31-I32 -> 392 | N31: =N32 -> 122.41935 | O31: =L31 -> 95 | P31: =N31-O31 -> 27.419355 | Q31: =H31-G31 -> 67.291667 | R31: =R32 -> 741.93548 | S31: =J31+K31+L31 -> 621 | T31: =R31-S31 -> 120.93548 | U31: =U32+N31 -> 1346.6129 | V31: =V32+O31 -> 858 | W31: =U31-V31 -> 488.6129 | X31: =X32+R31 -> 8161.2903 | Y31: =Y32+S31 -> 5695.5161 | Z31: =X31-Y31 -> 2465.7742 | AA31: =COS(ATAN(M31/S31)) -> 0.84561831
B32: 10 | C32: =C33+205 -> 279447 | D32: =D33+310 -> 593371 | E32: =E33+91 -> 143755 | F32: =C32+D32+E32 -> 1016573 | G32: =(C33+D33+E33)+((S32/24)*7.5) -> 1016156.4 | H32: =G32+((K32/12)*2.5) -> 1016221 | I32: =I33+377 -> 712111 | J32: =C32-C33 -> 205 | K32: =D32-D33 -> 310 | L32: =E32-E33 -> 91 | M32: =I32-I33 -> 377 | N32: =N33 -> 122.41935 | O32: =L32 -> 91 | P32: =N32-O32 -> 31.419355 | Q32: =H32-G32 -> 64.583333 | R32: =R33 -> 741.93548 | S32: =J32+K32+L32 -> 606 | T32: =R32-S32 -> 135.93548 | U32: =U33+N32 -> 1224.1935 | V32: =V33+O32 -> 763 | W32: =U32-V32 -> 461.19355 | X32: =X33+R32 -> 7419.3548 | Y32: =Y33+S32 -> 5074.5161 | Z32: =X32-Y32 -> 2344.8387 | AA32: =COS(ATAN(M32/S32)) -> 0.8490985
B33: 9 | C33: =C34+201 -> 279242 | D33: =D34+298 -> 593061 | E33: =E34+90 -> 143664 | F33: =C33+D33+E33 -> 1015967 | G33: =(C34+D34+E34)+((S33/24)*7.5) -> 1015562.1 | H33: =G33+((K33/12)*2.5) -> 1015624.1 | I33: =I34+396 -> 711734 | J33: =C33-C34 -> 201 | K33: =D33-D34 -> 298 | L33: =E33-E34 -> 90 | M33: =I33-I34 -> 396 | N33: =N34 -> 122.41935 | O33: =L33 -> 90 | P33: =N33-O33 -> 32.419355 | Q33: =H33-G33 -> 62.083333 | R33: =R34 -> 741.93548 | S33: =J33+K33+L33 -> 589 | T33: =R33-S33 -> 152.93548 | U33: =U34+N33 -> 1101.7742 | V33: =V34+O33 -> 672 | W33: =U33-V33 -> 429.77419 | X33: =X34+R33 -> 6677.4194 | Y33: =Y34+S33 -> 4468.5161 | Z33: =X33-Y33 -> 2208.9032 | AA33: =COS(ATAN(M33/S33)) -> 0.82987631
B34: 8 | C34: =C35+197 -> 279041 | D34: =D35+290 -> 592763 | E34: =E35+87 -> 143574 | F34: =C34+D34+E34 -> 1015378 | G34: =(C35+D35+E35)+((S34/24)*7.5) -> 1014983.4 | H34: =G34+((K34/12)*2.5) -> 1015043.8 | I34: =I35+383 -> 711338 | J34: =C34-C35 -> 197 | K34: =D34-D35 -> 290 | L34: =E34-E35 -> 87 | M34: =I34-I35 -> 383 | N34: =N35 -> 122.41935 | O34: =L34 -> 87 | P34: =N34-O34 -> 35.419355 | Q34: =H34-G34 -> 60.416667 | R34: =R35 -> 741.93548 | S34: =J34+K34+L34 -> 574 | T34: =R34-S34 -> 167.93548 | U34: =U35+N34 -> 979.35484 | V34: =V35+O34 -> 582 | W34: =U34-V34 -> 397.35484 | X34: =X35+R34 -> 5935.4839 | Y34: =Y35+S34 -> 3879.5161 | Z34: =X34-Y34 -> 2055.9677 | AA34: =COS(ATAN(M34/S34)) -> 0.83182728
B35: 7 | C35: 278844 | D35: 592473 | E35: 143487 | F35: =C35+D35+E35 -> 1014804 | G35: =(C36+D36+E36)+((S35/24)*7.5) -> 1014434.8 | H35: =G35+((K35/12)*2.5) -> 1014491.1 | I35: 710955 | J35: =C35-C36 -> 181 | K35: =D35-D36 -> 270 | L35: =E35-E36 -> 86 | M35: =I35-I36 -> 375 | N35: =N36 -> 122.41935 | O35: =L35 -> 86 | P35: =N35-O35 -> 36.419355 | Q35: =H35-G35 -> 56.25 | R35: =R36 -> 741.93548 | S35: =J35+K35+L35 -> 537 | T35: =R35-S35 -> 204.93548 | U35: =U36+N35 -> 856.93548 | V35: =V36+O35 -> 495 | W35: =U35-V35 -> 361.93548 | X35: =X36+R35 -> 5193.5484 | Y35: =Y36+S35 -> 3305.5161 | Z35: =X35-Y35 -> 1888.0323 | AA35: =COS(ATAN(M35/S35)) -> 0.81987695
B36: 6 | C36: =C37+175 -> 278663 | D36: =D37+252 -> 592203 | E36: =E37+84 -> 143401 | F36: =C36+D36+E36 -> 1014267 | G36: =(C37+D37+E37)+((S36/24)*7.5) -> 1013915.7 | H36: =G36+((K36/12)*2.5) -> 1013968.2 | I36: =I37+390 -> 710580 | J36: =C36-C37 -> 175 | K36: =D36-D37 -> 252 | L36: =E36-E37 -> 84 | M36: =I36-I37 -> 390 | N36: =N37 -> 122.41935 | O36: =L36 -> 84 | P36: =N36-O36 -> 38.419355 | Q36: =H36-G36 -> 52.5 | R36: =R37 -> 741.93548 | S36: =J36+K36+L36 -> 511 | T36: =R36-S36 -> 230.93548 | U36: =U37+N36 -> 734.51613 | V36: =V37+O36 -> 409 | W36: =U36-V36 -> 325.51613 | X36: =X37+R36 -> 4451.6129 | Y36: =Y37+S36 -> 2768.5161 | Z36: =X36-Y36 -> 1683.0968 | AA36: =COS(ATAN(M36/S36)) -> 0.7949315
B37: 5 | C37: =C38+159 -> 278488 | D37: =D38+239 -> 591951 | E37: =E38+74 -> 143317 | F37: =C37+D37+E37 -> 1013756 | G37: =(C38+D38+E38)+((S37/24)*7.5) -> 1013431.5 | H37: =G37+((K37/12)*2.5) -> 1013481.3 | I37: =I38+369 -> 710190 | J37: =C37-C38 -> 159 | K37: =D37-D38 -> 239 | L37: =E37-E38 -> 74 | M37: =I37-I38 -> 369 | N37: =N38 -> 122.41935 | O37: =L37 -> 74 | P37: =N37-O37 -> 48.419355 | Q37: =H37-G37 -> 49.791667 | R37: =R38 -> 741.93548 | S37: =J37+K37+L37 -> 472 | T37: =R37-S37 -> 269.93548 | U37: =U38+N37 -> 612.09677 | V37: =V38+O37 -> 325 | W37: =U37-V37 -> 287.09677 | X37: =X38+R37 -> 3709.6774 | Y37: =Y38+S37 -> 2257.5161 | Z37: =X37-Y37 -> 1452.1613 | AA37: =COS(ATAN(M37/S37)) -> 0.78782189
B38: 4 | C38: =C39+153 -> 278329 | D38: =D39+240 -> 591712 | E38: =E39+73 -> 143243 | F38: =C38+D38+E38 -> 1013284 | G38: =(C39+D39+E39)+((S38/24)*7.5) -> 1012963.6 | H38: =G38+((K38/12)*2.5) -> 1013013.6 | I38: =I39+372 -> 709821 | J38: =C38-C39 -> 153 | K38: =D38-D39 -> 240 | L38: =E38-E39 -> 73 | M38: =I38-I39 -> 372 | N38: =N39 -> 122.41935 | O38: =L38 -> 73 | P38: =N38-O38 -> 49.419355 | Q38: =H38-G38 -> 50 | R38: =R39 -> 741.93548 | S38: =J38+K38+L38 -> 466 | T38: =R38-S38 -> 275.93548 | U38: =U39+N38 -> 489.67742 | V38: =V39+O38 -> 251 | W38: =U38-V38 -> 238.67742 | X38: =X39+R38 -> 2967.7419 | Y38: =Y39+S38 -> 1785.5161 | Z38: =X38-Y38 -> 1182.2258 | AA38: =COS(ATAN(M38/S38)) -> 0.78152285
B39: 3 | C39: =C40+157 -> 278176 | D39: =D40+230 -> 591472 | E39: =E40+67 -> 143170 | F39: =C39+D39+E39 -> 1012818 | G39: =(C40+D40+E40)+((S39/24)*7.5) -> 1012505.9 | H39: =G39+((K39/12)*2.5) -> 1012553.8 | I39: =I40+368 -> 709449 | J39: =C39-C40 -> 157 | K39: =D39-D40 -> 230 | L39: =E39-E40 -> 67 | M39: =I39-I40 -> 368 | N39: =N40 -> 122.41935 | O39: =L39 -> 67 | P39: =N39-O39 -> 55.419355 | Q39: =H39-G39 -> 47.916667 | R39: =R40 -> 741.93548 | S39: =J39+K39+L39 -> 454 | T39: =R39-S39 -> 287.93548 | U39: =U40+N39 -> 367.25806 | V39: =V40+O39 -> 178 | W39: =U39-V39 -> 189.25806 | X39: =X40+R39 -> 2225.8065 | Y39: =Y40+S39 -> 1319.5161 | Z39: =X39-Y39 -> 906.29032 | AA39: =COS(ATAN(M39/S39)) -> 0.77684624
B40: 2 | C40: =C41+142 -> 278019 | D40: =D41+227 -> 591242 | E40: =E41+52 -> 143103 | F40: =C40+D40+E40 -> 1012364 | G40: =(C41+D41+E41)+((S40/24)*7.5) -> 1012074.6 | H40: =G40+((K40/12)*2.5) -> 1012121.9 | I40: =I41+339 -> 709081 | J40: =C40-C41 -> 142 | K40: =D40-D41 -> 227 | L40: =E40-E41 -> 52 | M40: =I40-I41 -> 339 | N40: =N41 -> 122.41935 | O40: =L40 -> 52 | P40: =N40-O40 -> 70.419355 | Q40: =H40-G40 -> 47.291667 | R40: =R41 -> 741.93548 | S40: =J40+K40+L40 -> 421 | T40: =R40-S40 -> 320.93548 | U40: =U41+N40 -> 244.83871 | V40: =V41+O40 -> 111 | W40: =U40-V40 -> 133.83871 | X40: =X41+R40 -> 1483.871 | Y40: =Y41+S40 -> 865.51613 | Z40: =X40-Y40 -> 618.35484 | AA40: =COS(ATAN(M40/S40)) -> 0.77887942
B41: 1 | C41: =C42+150 -> 277877 | D41: =D42+220 -> 591015 | E41: =E42+59 -> 143051 | F41: =C41+D41+E41 -> 1011943 | G41: =(C42+D42+E42)+((S41/24)*7.5) -> 1011652.9 | H41: =G41+((K41/12)*2.5) -> 1011698.7 | I41: =I42+334 -> 708742 | J41: =C41-C42 -> 150 | K41: =D41-D42 -> 220 | L41: =E41-E42 -> 59 | M41: =I41-I42 -> 334 | N41: =O6/31 -> 122.41935 | O41: =L41 -> 59 | P41: =N41-O41 -> 63.419355 | Q41: =H41-G41 -> 45.833333 | R41: =S6/31 -> 741.93548 | S41: =J41+K41+L41+V6 -> 444.51613 | T41: =R41-S41 -> 297.41935 | U41: =N41 -> 122.41935 | V41: =O41 -> 59 | W41: =U41-V41 -> 63.419355 | X41: =R41 -> 741.93548 | Y41: =S41 -> 444.51613 | Z41: =X41-Y41 -> 297.41935 | AA41: =COS(ATAN(M41/S41)) -> 0.79947058
B42: cierre mes anterior | C42: 277727 | D42: 590795 | E42: 142992 | F42: 1011514 | G42: 1011272.3 | H42: 1011310.5 | I42: 708408 | M42: =SUM(M11:M41) -> 10158 | AA42: =AVERAGE(AA11:AA41) -> 0.83264467
...

Sheet Ciencia A
G2: ANEXO No. 1.
G3: TABLA 1A
G4: Cumplimiento del plan de consumo de energía eléctrica total, mes: | N4: ='Cocina C'!N4 -> 45658
C5: SERVICIO: CIENCIA ANIMAL | U5: total | V5: diaria
N6: Plan Pico N | O6: =S6*16.5% -> 4620 | P6: Plan Pico D | Q6: =(S6*8)/100 -> 2240 | R6: PLAN MES | S6: 28000 | T6: Perdidas: | U6: 1079 | V6: =U6/31 -> 34.806452
B7: Día | C7: Lectura del contador | J7: Consumo diario kWh y kvarh | N7: Consumo diario Pico nocturno kWh | Q7: Consumo diario pico Diurno kWh | R7: Consumo diario total kWh | U7: Consumo acumulado Pico kWh | X7: Consumo acumulado Total kWh | AB7: Firma Responsable
C8: MAD | D8: DIA | E8: PICO | F8: TOTAL | G8: Pico Diurno 11 am | H8: Pico Diurno 1 pm | I8: REACT | J8: MAD | K8: DIA | L8: PICO | M8: REACT | N8: Plan Pico | O8: Real Pico | P8: Plan - Real | R8: Plan | S8: Real | T8: Plan - Real | U8: Plan Pico | V8: Real Pico | W8: Plan - Real | X8: Plan | Y8: Real | Z8: Plan - Real | AA8: FP
C9: 1 | D9: 2 | E9: 3 | G9: 4 | H9: 5 | I9: 6 | J9: 7 | K9: 8 | L9: 9 | M9: 10 | N9: 11 | O9: 12 | P9: 13 | Q9: 14 | R9: 15 | S9: 16 | T9: 17 | U9: 18 | V9: 19 | W9: 20 | X9: 21 | Y9: 22 | Z9: 23 | AA9: 24 | AB9: 25
B11: 31 | C11: 244947 | D11: 538685 | E11: 119674 | F11: =C11+D11+E11 -> 903306 | G11: =(C12+D12+E12)+((S11/24)*9.5) -> 903248.6 | H11: =G11+((K11/12)*2.5) -> 903248.6 | I11: 98988 | J11: =C11-C12 -> 95 | K11: =D11-D12 -> 0 | L11: =E11-E12 -> 0 | M11: =I11-I12 -> 18 | N11: =N12 -> 149.03226 | O11: =L11 -> 0 | P11: =N11-O11 -> 149.03226 | Q11: =H11-G11 -> 0 | R11: =R12 -> 903.22581 | S11: =J11+K11+L11 -> 95 | T11: =R11-S11 -> 808.22581 | U11: =U12+N11 -> 4620 | V11: =V12+O11 -> 1679 | W11: =U11-V11 -> 2941 | X11: =X12+R11 -> 28000 | Y11: =Y12+S11 -> 11473 | Z11: =X11-Y11 -> 16527 | AA11: =COS(ATAN(M11/S11)) -> 0.98251915
B12: 30 | C12: =C13+98 -> 244852 | D12: 538685 | E12: 119674 | F12: =C12+D12+E12 -> 903211 | G12: =(C13+D13+E13)+((S12/24)*3) -> 903125.25 | H12: =G12+((K12/12)*2.5) -> 903125.25 | I12: =I13+21 -> 98970 | J12: =C12-C13 -> 98 | K12: =D12-D13 -> 0 | L12: =E12-E13 -> 0 | M12: =I12-I13 -> 21 | N12: =N13 -> 149.03226 | O12: =L12 -> 0 | P12: =N12-O12 -> 149.03226 | Q12: =H12-G12 -> 0 | R12: =R13 -> 903.22581 | S12: =J12+K12+L12 -> 98 | T12: =R12-S12 -> 805.22581 | U12: =U13+N12 -> 4470.9677 | V12: =V13+O12 -> 1679 | W12: =U12-V12 -> 2791.9677 | X12: =X13+R12 -> 27096.774 | Y12: =Y13+S12 -> 11378 | Z12: =X12-Y12 -> 15718.774 | AA12: =COS(ATAN(M12/S12)) -> 0.97780241
B13: 29 | C13: =C14+102 -> 244754 | D13: 538685 | E13: =E14+34 -> 119674 | F13: =C13+D13+E13 -> 903113 | G13: =(C14+D14+E14)+((S13/24)*3) -> 902926.62 | H13: =G13+((K13/12)*2.5) -> 902942.67 | I13: =I14+23 -> 98949 | J13: =C13-C14 -> 102 | K13: =D13-D14 -> 77 | L13: =E13-E14 -> 34 | M13: =I13-I14 -> 23 | N13: =N14 -> 149.03226 | O13: =L13 -> 34 | P13: =N13-O13 -> 115.03226 | Q13: =H13-G13 -> 16.041667 | R13: =R14 -> 903.22581 | S13: =J13+K13+L13 -> 213 | T13: =R13-S13 -> 690.22581 | U13: =U14+N13 -> 4321.9355 | V13: =V14+O13 -> 1679 | W13: =U13-V13 -> 2642.9355 | X13: =X14+R13 -> 26193.548 | Y13: =Y14+S13 -> 11280 | Z13: =X13-Y13 -> 14913.548 | AA13: =COS(ATAN(M13/S13)) -> 0.99422052
B14: 28 | C14: =C15+216 -> 244652 | D14: =D15+352 -> 538608 | E14: =E15+92 -> 119640 | F14: =C14+D14+E14 -> 902900 | G14: =(C15+D15+E15)+((S14/24)*3) -> 902322.5 | H14: =G14+((K14/12)*2.5) -> 902395.83 | I14: =I15+68 -> 98926 | J14: =C14-C15 -> 216 | K14: =D14-D15 -> 352 | L14: =E14-E15 -> 92 | M14: =I14-I15 -> 68 | N14: =N15 -> 149.03226 | O14: =L14 -> 92 | P14: =N14-O14 -> 57.032258 | Q14: =H14-G14 -> 73.333333 | R14: =R15 -> 903.22581 | S14: =J14+K14+L14 -> 660 | T14: =R14-S14 -> 243.22581 | U14: =U15+N14 -> 4172.9032 | V14: =V15+O14 -> 1645 | W14: =U14-V14 -> 2527.9032 | X14: =X15+R14 -> 25290.323 | Y14: =Y15+S14 -> 11067 | Z14: =X14-Y14 -> 14223.323 | AA14: =COS(ATAN(M14/S14)) -> 0.99473426
B15: 27 | C15: 244436 | D15: 538256 | E15: 119548 | F15: =C15+D15+E15 -> 902240 | G15: =(C16+D16+E16)+((S15/24)*3) -> 901656.38 | H15: =G15+((K15/12)*2.5) -> 901732.62 | I15: 98858 | J15: =C15-C16 -> 208 | K15: =D15-D16 -> 366 | L15: =E15-E16 -> 93 | M15: =I15-I16 -> 67 | N15: =N16 -> 149.03226 | O15: =L15 -> 93 | P15: =N15-O15 -> 56.032258 | Q15: =H15-G15 -> 76.25 | R15: =R16 -> 903.22581 | S15: =J15+K15+L15 -> 667 | T15: =R15-S15 -> 236.22581 | U15: =U16+N15 -> 4023.871 | V15: =V16+O15 -> 1553 | W15: =U15-V15 -> 2470.871 | X15: =X16+R15 -> 24387.097 | Y15: =Y16+S15 -> 10407 | Z15: =X15-Y15 -> 13980.097 | AA15: =COS(ATAN(M15/S15)) -> 0.99499278
B16: 26 | C16: =C17+209 -> 244228 | D16: =D17+335 -> 537890 | E16: =E17+90 -> 119455 | F16: =C16+D16+E16 -> 901573 | G16: =(C17+D17+E17)+((S16/24)*3) -> 901018.25 | H16: =G16+((K16/12)*2.5) -> 901088.04 | I16: =I17+62 -> 98791 | J16: =C16-C17 -> 209 | K16: =D16-D17 -> 335 | L16: =E16-E17 -> 90 | M16: =I16-I17 -> 62 | N16: =N17 -> 149.03226 | O16: =L16 -> 90 | P16: =N16-O16 -> 59.032258 | Q16: =H16-G16 -> 69.791667 | R16: =R17 -> 903.22581 | S16: =J16+K16+L16 -> 634 | T16: =R16-S16 -> 269.22581 | U16: =U17+N16 -> 3874.8387 | V16: =V17+O16 -> 1460 | W16: =U16-V16 -> 2414.8387 | X16: =X17+R16 -> 23483.871 | Y16: =Y17+S16 -> 9740 | Z16: =X16-Y16 -> 13743.871 | AA16: =COS(ATAN(M16/S16)) -> 0.99525241
B17: 25 | C17: =C18+205 -> 244019 | D17: =D18+305 -> 537555 | E17: =E18+88 -> 119365 | F17: =C17+D17+E17 -> 900939 | G17: =(C18+D18+E18)+((S17/24)*3) -> 900415.75 | H17: =G17+((K17/12)*2.5) -> 900479.29 | I17: =I18+65 -> 98729 | J17: =C17-C18 -> 205 | K17: =D17-D18 -> 305 | L17: =E17-E18 -> 88 | M17: =I17-I18 -> 65 | N17: =N18 -> 149.03226 | O17: =L17 -> 88 | P17: =N17-O17 -> 61.032258 | Q17: =H17-G17 -> 63.541667 | R17: =R18 -> 903.22581 | S17: =J17+K17+L17 -> 598 | T17: =R17-S17 -> 305.22581 | U17: =U18+N17 -> 3725.8065 | V17: =V18+O17 -> 1370 | W17: =U17-V17 -> 2355.8065 | X17: =X18+R17 -> 22580.645 | Y17: =Y18+S17 -> 9106 | Z17: =X17-Y17 -> 13474.645 | AA17: =COS(ATAN(M17/S17)) -> 0.99414446
B18: 24 | C18: =C19+203 -> 243814 | D18: =D19+290 -> 537250 | E18: =E19+83 -> 119277 | F18: =C18+D18+E18 -> 900341 | G18: =(C19+D19+E19)+((S18/24)*3) -> 899837 | H18: =G18+((K18/12)*2.5) -> 899897.42 | I18: =I19+60 -> 98664 | J18: =C18-C19 -> 203 | K18: =D18-D19 -> 290 | L18: =E18-E19 -> 83 | M18: =I18-I19 -> 60 | N18: =N19 -> 149.03226 | O18: =L18 -> 83 | P18: =N18-O18 -> 66.032258 | Q18: =H18-G18 -> 60.416667 | R18: =R19 -> 903.22581 | S18: =J18+K18+L18 -> 576 | T18: =R18-S18 -> 327.22581 | U18: =U19+N18 -> 3576.7742 | V18: =V19+O18 -> 1282 | W18: =U18-V18 -> 2294.7742 | X18: =X19+R18 -> 21677.419 | Y18: =Y19+S18 -> 8508 | Z18: =X18-Y18 -> 13169.419 | AA18: =COS(ATAN(M18/S18)) -> 0.99461841
B19: 23 | C19: =C20+190 -> 243611 | D19: =D20+210 -> 536960 | E19: =E20+76 -> 119194 | F19: =C19+D19+E19 -> 899765 | G19: =(C20+D20+E20)+((S19/24)*3) -> 899348.5 | H19: =G19+((K19/12)*2.5) -> 899392.25 | I19: =I20+51 -> 98604 | J19: =C19-C20 -> 190 | K19: =D19-D20 -> 210 | L19: =E19-E20 -> 76 | M19: =I19-I20 -> 51 | N19: =N20 -> 149.03226 | O19: =L19 -> 76 | P19: =N19-O19 -> 73.032258 | Q19: =H19-G19 -> 43.75 | R19: =R20 -> 903.22581 | S19: =J19+K19+L19 -> 476 | T19: =R19-S19 -> 427.22581 | U19: =U20+N19 -> 3427.7419 | V19: =V20+O19 -> 1199 | W19: =U19-V19 -> 2228.7419 | X19: =X20+R19 -> 20774.194 | Y19: =Y20+S19 -> 7932 | Z19: =X19-Y19 -> 12842.194 | AA19: =COS(ATAN(M19/S19)) -> 0.99430915
B20: 22 | C20: 243421 | D20: 536750 | E20: 119118 | F20: =C20+D20+E20 -> 899289 | G20: =(C21+D21+E21)+((S20/24)*3) -> 899026.5 | H20: =G20+((K20/12)*2.5) -> 899054.83 | I20: 98553 | J20: =C20-C21 -> 110 | K20: =D20-D21 -> 136 | L20: =E20-E21 -> 54 | M20: =I20-I21 -> 29 | N20: =N21 -> 149.03226 | O20: =L20 -> 54 | P20: =N20-O20 -> 95.032258 | Q20: =H20-G20 -> 28.333333 | R20: =R21 -> 903.22581 | S20: =J20+K20+L20 -> 300 | T20: =R20-S20 -> 603.22581 | U20: =U21+N20 -> 3278.7097 | V20: =V21+O20 -> 1123 | W20: =U20-V20 -> 2155.7097 | X20: =X21+R20 -> 19870.968 | Y20: =Y21+S20 -> 7456 | Z20: =X20-Y20 -> 12414.968 | AA20: =COS(ATAN(M20/S20)) -> 0.99536027
B21: 21 | C21: =C22+108 -> 243311 | D21: =D22+133 -> 536614 | E21: =E22+47 -> 119064 | F21: =C21+D21+E21 -> 898989 | G21: =(C22+D22+E22)+((S21/24)*3) -> 898737 | H21: =G21+((K21/12)*2.5) -> 898764.71 | I21: =I22+32 -> 98524 | J21: =C21-C22 -> 108 | K21: =D21-D22 -> 133 | L21: =E21-E22 -> 47 | M21: =I21-I22 -> 32 | N21: =N22 -> 149.03226 | O21: =L21 -> 47 | P21: =N21-O21 -> 102.03226 | Q21: =H21-G21 -> 27.708333 | R21: =R22 -> 903.22581 | S21: =J21+K21+L21 -> 288 | T21: =R21-S21 -> 615.22581 | U21: =U22+N21 -> 3129.6774 | V21: =V22+O21 -> 1069 | W21: =U21-V21 -> 2060.6774 | X21: =X22+R21 -> 18967.742 | Y21: =Y22+S21 -> 7156 | Z21: =X21-Y21 -> 11811.742 | AA21: =COS(ATAN(M21/S21)) -> 0.99388373
B22: 20 | C22: =C23+109 -> 243203 | D22: =D23+132 -> 536481 | E22: =E23+50 -> 119017 | F22: =C22+D22+E22 -> 898701 | G22: =(C23+D23+E23)+((S22/24)*3) -> 898446.38 | H22: =G22+((K22/12)*2.5) -> 898473.88 | I22: =I23+33 -> 98492 | J22: =C22-C23 -> 109 | K22: =D22-D23 -> 132 | L22: =E22-E23 -> 50 | M22: =I22-I23 -> 33 | N22: =N23 -> 149.03226 | O22: =L22 -> 50 | P22: =N22-O22 -> 99.032258 | Q22: =H22-G22 -> 27.5 | R22: =R23 -> 903.22581 | S22: =J22+K22+L22 -> 291 | T22: =R22-S22 -> 612.22581 | U22: =U23+N22 -> 2980.6452 | V22: =V23+O22 -> 1022 | W22: =U22-V22 -> 1958.6452 | X22: =X23+R22 -> 18064.516 | Y22: =Y23+S22 -> 6868 | Z22: =X22-Y22 -> 11196.516 | AA22: =COS(ATAN(M22/S22)) -> 0.99363135
B23: 19 | C23: =C24+103 -> 243094 | D23: =D24+129 -> 536349 | E23: =E24+53 -> 118967 | F23: =C23+D23+E23 -> 898410 | G23: =(C24+D24+E24)+((S23/24)*3) -> 898160.62 | H23: =G23+((K23/12)*2.5) -> 898187.5 | I23: =I24+28 -> 98459 | J23: =C23-C24 -> 103 | K23: =D23-D24 -> 129 | L23: =E23-E24 -> 53 | M23: =I23-I24 -> 28 | N23: =N24 -> 149.03226 | O23: =L23 -> 53 | P23: =N23-O23 -> 96.032258 | Q23: =H23-G23 -> 26.875 | R23: =R24 -> 903.22581 | S23: =J23+K23+L23 -> 285 | T23: =R23-S23 -> 618.22581 | U23: =U24+N23 -> 2831.6129 | V23: =V24+O23 -> 972 | W23: =U23-V23 -> 1859.6129 | X23: =X24+R23 -> 17161.29 | Y23: =Y24+S23 -> 6577 | Z23: =X23-Y23 -> 10584.29 | AA23: =COS(ATAN(M23/S23)) -> 0.99520856
B24: 18 | C24: =C25+107 -> 242991 | D24: =D25+127 -> 536220 | E24: =E25+46 -> 118914 | F24: =C24+D24+E24 -> 898125 | G24: =(C25+D25+E25)+((S24/24)*3) -> 897880 | H24: =G24+((K24/12)*2.5) -> 897906.46 | I24: =I25+30 -> 98431 | J24: =C24-C25 -> 107 | K24: =D24-D25 -> 127 | L24: =E24-E25 -> 46 | M24: =I24-I25 -> 30 | N24: =N25 -> 149.03226 | O24: =L24 -> 46 | P24: =N24-O24 -> 103.03226 | Q24: =H24-G24 -> 26.458333 | R24: =R25 -> 903.22581 | S24: =J24+K24+L24 -> 280 | T24: =R24-S24 -> 623.22581 | U24: =U25+N24 -> 2682.5806 | V24: =V25+O24 -> 919 | W24: =U24-V24 -> 1763.5806 | X24: =X25+R24 -> 16258.065 | Y24: =Y25+S24 -> 6292 | Z24: =X24-Y24 -> 9966.0645 | AA24: =COS(ATAN(M24/S24)) -> 0.99430915
B25: 17 | C25: =C26+106 -> 242884 | D25: =D26+133 -> 536093 | E25: =E26+49 -> 118868 | F25: =C25+D25+E25 -> 897845 | G25: =(C26+D26+E26)+((S25/24)*3) -> 897593 | H25: =G25+((K25/12)*2.5) -> 897620.71 | I25: =I26+32 -> 98401 | J25: =C25-C26 -> 106 | K25: =D25-D26 -> 133 | L25: =E25-E26 -> 49 | M25: =I25-I26 -> 32 | N25: =N26 -> 149.03226 | O25: =L25 -> 49 | P25: =N25-O25 -> 100.03226 | Q25: =H25-G25 -> 27.708333 | R25: =R26 -> 903.22581 | S25: =J25+K25+L25 -> 288 | T25: =R25-S25 -> 615.22581 | U25: =U26+N25 -> 2533.5484 | V25: =V26+O25 -> 873 | W25: =U25-V25 -> 1660.5484 | X25: =X26+R25 -> 15354.839 | Y25: =Y26+S25 -> 6012 | Z25: =X25-Y25 -> 9342.8387 | AA25: =COS(ATAN(M25/S25)) -> 0.99388373
B26: 16 | C26: =C27+102 -> 242778 | D26: =D27+130 -> 535960 | E26: =E27+44 -> 118819 | F26: =C26+D26+E26 -> 897557 | G26: =(C27+D27+E27)+((S26/24)*3) -> 897315.5 | H26: =G26+((K26/12)*2.5) -> 897342.58 | I26: =I27+31 -> 98369 | J26: =C26-C27 -> 102 | K26: =D26-D27 -> 130 | L26: =E26-E27 -> 44 | M26: =I26-I27 -> 31 | N26: =N27 -> 149.03226 | O26: =L26 -> 44 | P26: =N26-O26 -> 105.03226 | Q26: =H26-G26 -> 27.083333 | R26: =R27 -> 903.22581 | S26: =J26+K26+L26 -> 276 | T26: =R26-S26 -> 627.22581 | U26: =U27+N26 -> 2384.5161 | V26: =V27+O26 -> 824 | W26: =U26-V26 -> 1560.5161 | X26: =X27+R26 -> 14451.613 | Y26: =Y27+S26 -> 5724 | Z26: =X26-Y26 -> 8727.6129 | AA26: =COS(ATAN(M26/S26)) -> 0.9937513
B27: 15 | C27: =C28+110 -> 242676 | D27: =D28+151 -> 535830 | E27: =E28+48 -> 118775 | F27: =C27+D27+E27 -> 897281 | G27: =(C28+D28+E28)+((S27/24)*3) -> 897010.62 | H27: =G27+((K27/12)*2.5) -> 897042.08 | I27: =I28+42 -> 98338 | J27: =C27-C28 -> 110 | K27: =D27-D28 -> 151 | L27: =E27-E28 -> 48 | M27: =I27-I28 -> 42 | N27: =N28 -> 149.03226 | O27: =L27 -> 48 | P27: =N27-O27 -> 101.03226 | Q27: =H27-G27 -> 31.458333 | R27: =R28 -> 903.22581 | S27: =J27+K27+L27 -> 309 | T27: =R27-S27 -> 594.22581 | U27: =U28+N27 -> 2235.4839 | V27: =V28+O27 -> 780 | W27: =U27-V27 -> 1455.4839 | X27: =X28+R27 -> 13548.387 | Y27: =Y28+S27 -> 5448 | Z27: =X27-Y27 -> 8100.3871 | AA27: =COS(ATAN(M27/S27)) -> 0.99088862
B28: 14 | C28: =C29+120 -> 242566 | D28: =D29+227 -> 535679 | E28: =E29+50 -> 118727 | F28: =C28+D28+E28 -> 896972 | G28: =(C29+D29+E29)+((S28/24)*3) -> 896624.62 | H28: =G28+((K28/12)*2.5) -> 896671.92 | I28: =I29+45 -> 98296 | J28: =C28-C29 -> 120 | K28: =D28-D29 -> 227 | L28: =E28-E29 -> 50 | M28: =I28-I29 -> 45 | N28: =N29 -> 149.03226 | O28: =L28 -> 50 | P28: =N28-O28 -> 99.032258 | Q28: =H28-G28 -> 47.291667 | R28: =R29 -> 903.22581 | S28: =J28+K28+L28 -> 397 | T28: =R28-S28 -> 506.22581 | U28: =U29+N28 -> 2086.4516 | V28: =V29+O28 -> 732 | W28: =U28-V28 -> 1354.4516 | X28: =X29+R28 -> 12645.161 | Y28: =Y29+S28 -> 5139 | Z28: =X28-Y28 -> 7506.1613 | AA28: =COS(ATAN(M28/S28)) -> 0.99363712
B29: 13 | C29: 242446 | D29: 535452 | E29: 118677 | F29: =C29+D29+E29 -> 896575 | G29: =(C30+D30+E30)+((S29/24)*3) -> 896216.25 | H29: =G29+((K29/12)*2.5) -> 896267.29 | I29: 98251 | J29: =C29-C30 -> 118 | K29: =D29-D30 -> 245 | L29: =E29-E30 -> 47 | M29: =I29-I30 -> 57 | N29: =N30 -> 149.03226 | O29: =L29 -> 47 | P29: =N29-O29 -> 102.03226 | Q29: =H29-G29 -> 51.041667 | R29: =R30 -> 903.22581 | S29: =J29+K29+L29 -> 410 | T29: =R29-S29 -> 493.22581 | U29: =U30+N29 -> 1937.4194 | V29: =V30+O29 -> 682 | W29: =U29-V29 -> 1255.4194 | X29: =X30+R29 -> 11741.935 | Y29: =Y30+S29 -> 4742 | Z29: =X29-Y29 -> 6999.9355 | AA29: =COS(ATAN(M29/S29)) -> 0.99047398
B30: 12 | C30: =C31+115 -> 242328 | D30: =D31+249 -> 535207 | E30: =E31+53 -> 118630 | F30: =C30+D30+E30 -> 896165 | G30: =(C31+D31+E31)+((S30/24)*3) -> 895800.12 | H30: =G30+((K30/12)*2.5) -> 895852 | I30: =I31+51 -> 98194 | J30: =C30-C31 -> 115 | K30: =D30-D31 -> 249 | L30: =E30-E31 -> 53 | M30: =I30-I31 -> 51 | N30: =N31 -> 149.03226 | O30: =L30 -> 53 | P30: =N30-O30 -> 96.032258 | Q30: =H30-G30 -> 51.875 | R30: =R31 -> 903.22581 | S30: =J30+K30+L30 -> 417 | T30: =R30-S30 -> 486.22581 | U30: =U31+N30 -> 1788.3871 | V30: =V31+O30 -> 635 | W30: =U30-V30 -> 1153.3871 | X30: =X31+R30 -> 10838.71 | Y30: =Y31+S30 -> 4332 | Z30: =X30-Y30 -> 6506.7097 | AA30: =COS(ATAN(M30/S30)) -> 0.99260396
B31: 11 | C31: =C32+111 -> 242213 | D31: =D32+222 -> 534958 | E31: =E32+50 -> 118577 | F31: =C31+D31+E31 -> 895748 | G31: =(C32+D32+E32)+((S31/24)*3) -> 895412.88 | H31: =G31+((K31/12)*2.5) -> 895459.12 | I31: =I32+46 -> 98143 | J31: =C31-C32 -> 111 | K31: =D31-D32 -> 222 | L31: =E31-E32 -> 50 | M31: =I31-I32 -> 46 | N31: =N32 -> 149.03226 | O31: =L31 -> 50 | P31: =N31-O31 -> 99.032258 | Q31: =H31-G31 -> 46.25 | R31: =R32 -> 903.22581 | S31: =J31+K31+L31 -> 383 | T31: =R31-S31 -> 520.22581 | U31: =U32+N31 -> 1639.3548 | V31: =V32+O31 -> 582 | W31: =U31-V31 -> 1057.3548 | X31: =X32+R31 -> 9935.4839 | Y31: =Y32+S31 -> 3915 | Z31: =X31-Y31 -> 6020.4839 | AA31: =COS(ATAN(M31/S31)) -> 0.99286457
B32: 10 | C32: =C33+109 -> 242102 | D32: =D33+217 -> 534736 | E32: =E33+52 -> 118527 | F32: =C32+D32+E32 -> 895365 | G32: =(C33+D33+E33)+((S32/24)*3) -> 895034.25 | H32: =G32+((K32/12)*2.5) -> 895079.46 | I32: =I33+44 -> 98097 | J32: =C32-C33 -> 109 | K32: =D32-D33 -> 217 | L32: =E32-E33 -> 52 | M32: =I32-I33 -> 44 | N32: =N33 -> 149.03226 | O32: =L32 -> 52 | P32: =N32-O32 -> 97.032258 | Q32: =H32-G32 -> 45.208333 | R32: =R33 -> 903.22581 | S32: =J32+K32+L32 -> 378 | T32: =R32-S32 -> 525.22581 | U32: =U33+N32 -> 1490.3226 | V32: =V33+O32 -> 532 | W32: =U32-V32 -> 958.32258 | X32: =X33+R32 -> 9032.2581 | Y32: =Y33+S32 -> 3532 | Z32: =X32-Y32 -> 5500.2581 | AA32: =COS(ATAN(M32/S32)) -> 0.99329335
B33: 9 | C33: =C34+117 -> 241993 | D33: =D34+210 -> 534519 | E33: =E34+54 -> 118475 | F33: =C33+D33+E33 -> 894987 | G33: =(C34+D34+E34)+((S33/24)*3) -> 894653.62 | H33: =G33+((K33/12)*2.5) -> 894697.38 | I33: =I34+41 -> 98053 | J33: =C33-C34 -> 117 | K33: =D33-D34 -> 210 | L33: =E33-E34 -> 54 | M33: =I33-I34 -> 41 | N33: =N34 -> 149.03226 | O33: =L33 -> 54 | P33: =N33-O33 -> 95.032258 | Q33: =H33-G33 -> 43.75 | R33: =R34 -> 903.22581 | S33: =J33+K33+L33 -> 381 | T33: =R33-S33 -> 522.22581 | U33: =U34+N33 -> 1341.2903 | V33: =V34+O33 -> 480 | W33: =U33-V33 -> 861.29032 | X33: =X34+R33 -> 8129.0323 | Y33: =Y34+S33 -> 3154 | Z33: =X33-Y33 -> 4975.0323 | AA33: =COS(ATAN(M33/S33)) -> 0.99425969
B34: 8 | C34: =C35+113 -> 241876 | D34: =D35+190 -> 534309 | E34: =E35+51 -> 118421 | F34: =C34+D34+E34 -> 894606 | G34: =(C35+D35+E35)+((S34/24)*3) -> 894296.25 | H34: =G34+((K34/12)*2.5) -> 894335.83 | I34: =I35+38 -> 98012 | J34: =C34-C35 -> 113 | K34: =D34-D35 -> 190 | L34: =E34-E35 -> 51 | M34: =I34-I35 -> 38 | N34: =N35 -> 149.03226 | O34: =L34 -> 51 | P34: =N34-O34 -> 98.032258 | Q34: =H34-G34 -> 39.583333 | R34: =R35 -> 903.22581 | S34: =J34+K34+L34 -> 354 | T34: =R34-S34 -> 549.22581 | U34: =U35+N34 -> 1192.2581 | V34: =V35+O34 -> 426 | W34: =U34-V34 -> 766.25806 | X34: =X35+R34 -> 7225.8065 | Y34: =Y35+S34 -> 2773 | Z34: =X34-Y34 -> 4452.8065 | AA34: =COS(ATAN(M34/S34)) -> 0.99428788
B35: 7 | C35: 241763 | D35: 534119 | E35: 118370 | F35: =C35+D35+E35 -> 894252 | G35: =(C36+D36+E36)+((S35/24)*3) -> 893930 | H35: =G35+((K35/12)*2.5) -> 893967.71 | I35: 97974 | J35: =C35-C36 -> 122 | K35: =D35-D36 -> 181 | L35: =E35-E36 -> 65 | M35: =I35-I36 -> 19 | N35: =N36 -> 149.03226 | O35: =L35 -> 65 | P35: =N35-O35 -> 84.032258 | Q35: =H35-G35 -> 37.708333 | R35: =R36 -> 903.22581 | S35: =J35+K35+L35 -> 368 | T35: =R35-S35 -> 535.22581 | U35: =U36+N35 -> 1043.2258 | V35: =V36+O35 -> 375 | W35: =U35-V35 -> 668.22581 | X35: =X36+R35 -> 6322.5806 | Y35: =Y36+S35 -> 2419 | Z35: =X35-Y35 -> 3903.5806 | AA35: =COS(ATAN(M35/S35)) -> 0.99866981
B36: 6 | C36: =C37+118 -> 241641 | D36: =D37+177 -> 533938 | E36: =E37+63 -> 118305 | F36: =C36+D36+E36 -> 893884 | G36: =(C37+D37+E37)+((S36/24)*3) -> 893570.75 | H36: =G36+((K36/12)*2.5) -> 893607.62 | I36: =I37+17 -> 97955 | J36: =C36-C37 -> 118 | K36: =D36-D37 -> 177 | L36: =E36-E37 -> 63 | M36: =I36-I37 -> 17 | N36: =N37 -> 149.03226 | O36: =L36 -> 63 | P36: =N36-O36 -> 86.032258 | Q36: =H36-G36 -> 36.875 | R36: =R37 -> 903.22581 | S36: =J36+K36+L36 -> 358 | T36: =R36-S36 -> 545.22581 | U36: =U37+N36 -> 894.19355 | V36: =V37+O36 -> 310 | W36: =U36-V36 -> 584.19355 | X36: =X37+R36 -> 5419.3548 | Y36: =Y37+S36 -> 2051 | Z36: =X36-Y36 -> 3368.3548 | AA36: =COS(ATAN(M36/S36)) -> 0.99887444
B37: 5 | C37: =C38+118 -> 241523 | D37: =D38+179 -> 533761 | E37: =E38+59 -> 118242 | F37: =C37+D37+E37 -> 893526 | G37: =(C38+D38+E38)+((S37/24)*3) -> 893214.5 | H37: =G37+((K37/12)*2.5) -> 893251.79 | I37: =I38+19 -> 97938 | J37: =C37-C38 -> 118 | K37: =D37-D38 -> 179 | L37: =E37-E38 -> 59 | M37: =I37-I38 -> 19 | N37: =N38 -> 149.03226 | O37: =L37 -> 59 | P37: =N37-O37 -> 90.032258 | Q37: =H37-G37 -> 37.291667 | R37: =R38 -> 903.22581 | S37: =J37+K37+L37 -> 356 | T37: =R37-S37 -> 547.22581 | U37: =U38+N37 -> 745.16129 | V37: =V38+O37 -> 247 | W37: =U37-V37 -> 498.16129 | X37: =X38+R37 -> 4516.129 | Y37: =Y38+S37 -> 1693 | Z37: =X37-Y37 -> 2823.129 | AA37: =COS(ATAN(M37/S37)) -> 0.99857881
B38: 4 | C38: =C39+118 -> 241405 | D38: =D39+175 -> 533582 | E38: =E39+56 -> 118183 | F38: =C38+D38+E38 -> 893170 | G38: =(C39+D39+E39)+((S38/24)*3) -> 892864.62 | H38: =G38+((K38/12)*2.5) -> 892901.08 | I38: =I39+17 -> 97919 | J38: =C38-C39 -> 118 | K38: =D38-D39 -> 175 | L38: =E38-E39 -> 56 | M38: =I38-I39 -> 17 | N38: =N39 -> 149.03226 | O38: =L38 -> 56 | P38: =N38-O38 -> 93.032258 | Q38: =H38-G38 -> 36.458333 | R38: =R39 -> 903.22581 | S38: =J38+K38+L38 -> 349 | T38: =R38-S38 -> 554.22581 | U38: =U39+N38 -> 596.12903 | V38: =V39+O38 -> 188 | W38: =U38-V38 -> 408.12903 | X38: =X39+R38 -> 3612.9032 | Y38: =Y39+S38 -> 1337 | Z38: =X38-Y38 -> 2275.9032 | AA38: =COS(ATAN(M38/S38)) -> 0.99881575
B39: 3 | C39: =C40+118 -> 241287 | D39: =D40+170 -> 533407 | E39: =E40+48 -> 118127 | F39: =C39+D39+E39 -> 892821 | G39: =(C40+D40+E40)+((S39/24)*3) -> 892527 | H39: =G39+((K39/12)*2.5) -> 892562.42 | I39: =I40+15 -> 97902 | J39: =C39-C40 -> 118 | K39: =D39-D40 -> 170 | L39: =E39-E40 -> 48 | M39: =I39-I40 -> 15 | N39: =N40 -> 149.03226 | O39: =L39 -> 48 | P39: =N39-O39 -> 101.03226 | Q39: =H39-G39 -> 35.416667 | R39: =R40 -> 903.22581 | S39: =J39+K39+L39 -> 336 | T39: =R39-S39 -> 567.22581 | U39: =U40+N39 -> 447.09677 | V39: =V40+O39 -> 132 | W39: =U39-V39 -> 315.09677 | X39: =X40+R39 -> 2709.6774 | Y39: =Y40+S39 -> 988 | Z39: =X39-Y39 -> 1721.6774 | AA39: =COS(ATAN(M39/S39)) -> 0.99900499
B40: 2 | C40: =C41+118 -> 241169 | D40: =D41+169 -> 533237 | E40: =E41+43 -> 118079 | F40: =C40+D40+E40 -> 892485 | G40: =(C41+D41+E41)+((S40/24)*3) -> 892196.25 | H40: =G40+((K40/12)*2.5) -> 892231.46 | I40: =I41+12 -> 97887 | J40: =C40-C41 -> 118 | K40: =D40-D41 -> 169 | L40: =E40-E41 -> 43 | M40: =I40-I41 -> 12 | N40: =N41 -> 149.03226 | O40: =L40 -> 43 | P40: =N40-O40 -> 106.03226 | Q40: =H40-G40 -> 35.208333 | R40: =R41 -> 903.22581 | S40: =J40+K40+L40 -> 330 | T40: =R40-S40 -> 573.22581 | U40: =U41+N40 -> 298.06452 | V40: =V41+O40 -> 84 | W40: =U40-V40 -> 214.06452 | X40: =X41+R40 -> 1806.4516 | Y40: =Y41+S40 -> 652 | Z40: =X40-Y40 -> 1154.4516 | AA40: =COS(ATAN(M40/S40)) -> 0.9993395
B41: 1 | C41: =C42+118 -> 241051 | D41: =D42+163 -> 533068 | E41: =E42+41 -> 118036 | F41: =C41+D41+E41 -> 892155 | G41: =(C42+D42+E42)+((S41/24)*3) -> 891873.25 | H41: =G41+((K41/12)*2.5) -> 891907.21 | I41: =I42+10 -> 97875 | J41: =C41-C42 -> 118 | K41: =D41-D42 -> 163 | L41: =E41-E42 -> 41 | M41: =I41-I42 -> 10 | N41: =O6/31 -> 149.03226 | O41: =L41 -> 41 | P41: =N41-O41 -> 108.03226 | Q41: =H41-G41 -> 33.958333 | R41: =S6/31 -> 903.22581 | S41: =J41+K41+L41 -> 322 | T41: =R41-S41 -> 581.22581 | U41: =N41 -> 149.03226 | V41: =O41 -> 41 | W41: =U41-V41 -> 108.03226 | X41: =R41 -> 903.22581 | Y41: =S41 -> 322 | Z41: =X41-Y41 -> 581.22581 | AA41: =COS(ATAN(M41/S41)) -> 0.99951811
B42: cierre mes anterior | C42: 240933 | D42: 532905 | E42: 117995 | F42: 891833 | G42: 891635.44 | H42: 891663.77 | I42: 97865 | M42: =SUM(M11:M41) -> 1123 | AA42: =AVERAGE(AA11:AA41) -> 0.99412039
...

Sheet Preparatoria
G2: ANEXO No. 1.
G3: TABLA 1A
G4: Cumplimiento del plan de consumo de energía eléctrica total, mes: | N4: ='Ciencia A'!N4 -> 45658
C5: SERVICIO: PREPARATORIA | U5: total | V5: diaria
N6: Plan Pico N | O6: =S6*16.5% -> 1650 | P6: Plan Pico D | Q6: =(S6*8)/100 -> 800 | R6: PLAN MES | S6: 10000 | T6: Perdidas: | U6: 362 | V6: =U6/31 -> 11.677419
B7: Día | C7: Lectura del contador | J7: Consumo diario kWh y kvarh | N7: Consumo diario Pico nocturno kWh | Q7: Consumo diario pico Diurno kWh | R7: Consumo diario total kWh | U7: Consumo acumulado Pico kWh | X7: Consumo acumulado Total kWh | AB7: Firma Responsable
C8: MAD | D8: DIA | E8: PICO | F8: TOTAL | G8: Pico Diurno 11 am | H8: Pico Diurno 1 pm | I8: REACT | J8: MAD | K8: DIA | L8: PICO | M8: REACT | N8: Plan Pico | O8: Real Pico | P8: Plan - Real | R8: Plan | S8: Real | T8: Plan - Real | U8: Plan Pico | V8: Real Pico | W8: Plan - Real | X8: Plan | Y8: Real | Z8: Plan - Real | AA8: FP
C9: 1 | D9: 2 | E9: 3 | G9: 4 | H9: 5 | I9: 6 | J9: 7 | K9: 8 | L9: 9 | M9: 10 | N9: 11 | O9: 12 | P9: 13 | Q9: 14 | R9: 15 | S9: 16 | T9: 17 | U9: 18 | V9: 19 | W9: 20 | X9: 21 | Y9: 22 | Z9: 23 | AA9: 24 | AB9: 25
B11: 31 | C11: 255451 | D11: 510330 | E11: 168514 | F11: =C11+D11+E11 -> 934295 | G11: =(C12+D12+E12)+((S11/24)*9.5) -> 934264.79 | H11: =G11+((K11/12)*2.5) -> 934266.88 | I11: 298958 | J11: =C11-C12 -> 32 | K11: =D11-D12 -> 10 | L11: =E11-E12 -> 8 | M11: =I11-I12 -> 8 | N11: =N12 -> 53.225806 | O11: =L11 -> 8 | P11: =N11-O11 -> 45.225806 | Q11: =H11-G11 -> 2.0833333 | R11: =R12 -> 322.58065 | S11: =J11+K11+L11 -> 50 | T11: =R11-S11 -> 272.58065 | U11: =U12+N11 -> 1650 | V11: =V12+O11 -> 232 | W11: =U11-V11 -> 1418 | X11: =X12+R11 -> 10000 | Y11: =Y12+S11 -> 1736 | Z11: =X11-Y11 -> 8264 | AA11: =COS(ATAN(M11/S11)) -> 0.98744063
B12: 30 | C12: =C13+30 -> 255419 | D12: =D13+14 -> 510320 | E12: =E13+6 -> 168506 | F12: =C12+D12+E12 -> 934245 | G12: =(C13+D13+E13)+((S12/24)*7.5) -> 934210.62 | H12: =G12+((K12/12)*2.5) -> 934213.54 | I12: =I13+7 -> 298950 | J12: =C12-C13 -> 30 | K12: =D12-D13 -> 14 | L12: =E12-E13 -> 6 | M12: =I12-I13 -> 7 | N12: =N13 -> 53.225806 | O12: =L12 -> 6 | P12: =N12-O12 -> 47.225806 | Q12: =H12-G12 -> 2.9166667 | R12: =R13 -> 322.58065 | S12: =J12+K12+L12 -> 50 | T12: =R12-S12 -> 272.58065 | U12: =U13+N12 -> 1596.7742 | V12: =V13+O12 -> 224 | W12: =U12-V12 -> 1372.7742 | X12: =X13+R12 -> 9677.4194 | Y12: =Y13+S12 -> 1686 | Z12: =X12-Y12 -> 7991.4194 | AA12: =COS(ATAN(M12/S12)) -> 0.99034175
B13: 29 | C13: =C14+27 -> 255389 | D13: =D14+34 -> 510306 | E13: =E14+6 -> 168500 | F13: =C13+D13+E13 -> 934195 | G13: =(C14+D14+E14)+((S13/24)*7.5) -> 934148.94 | H13: =G13+((K13/12)*2.5) -> 934156.02 | I13: =I14+6 -> 298943 | J13: =C13-C14 -> 27 | K13: =D13-D14 -> 34 | L13: =E13-E14 -> 6 | M13: =I13-I14 -> 6 | N13: =N14 -> 53.225806 | O13: =L13 -> 6 | P13: =N13-O13 -> 47.225806 | Q13: =H13-G13 -> 7.0833333 | R13: =R14 -> 322.58065 | S13: =J13+K13+L13 -> 67 | T13: =R13-S13 -> 255.58065 | U13: =U14+N13 -> 1543.5484 | V13: =V14+O13 -> 218 | W13: =U13-V13 -> 1325.5484 | X13: =X14+R13 -> 9354.8387 | Y13: =Y14+S13 -> 1636 | Z13: =X13-Y13 -> 7718.8387 | AA13: =COS(ATAN(M13/S13)) -> 0.99601416
B14: 28 | C14: 255362 | D14: 510272 | E14: 168494 | F14: =C14+D14+E14 -> 934128 | G14: =(C15+D15+E15)+((S14/24)*7.5) -> 934062 | H14: =G14+((K14/12)*2.5) -> 934074.08 | I14: =I15+4 -> 298937 | J14: =C14-C15 -> 29 | K14: =D14-D15 -> 58 | L14: =E14-E15 -> 9 | M14: =I14-I15 -> 4 | N14: =N15 -> 53.225806 | O14: =L14 -> 9 | P14: =N14-O14 -> 44.225806 | Q14: =H14-G14 -> 12.083333 | R14: =R15 -> 322.58065 | S14: =J14+K14+L14 -> 96 | T14: =R14-S14 -> 226.58065 | U14: =U15+N14 -> 1490.3226 | V14: =V15+O14 -> 212 | W14: =U14-V14 -> 1278.3226 | X14: =X15+R14 -> 9032.2581 | Y14: =Y15+S14 -> 1569 | Z14: =X14-Y14 -> 7463.2581 | AA14: =COS(ATAN(M14/S14)) -> 0.99913307
B15: 27 | C15: =C16+28 -> 255333 | D15: =D16+53 -> 510214 | E15: =E16+12 -> 168485 | F15: =C15+D15+E15 -> 934032 | G15: =(C16+D16+E16)+((S15/24)*7.5) -> 933968.06 | H15: =G15+((K15/12)*2.5) -> 933979.1 | I15: =I16+5 -> 298933 | J15: =C15-C16 -> 28 | K15: =D15-D16 -> 53 | L15: =E15-E16 -> 12 | M15: =I15-I16 -> 5 | N15: =N16 -> 53.225806 | O15: =L15 -> 12 | P15: =N15-O15 -> 41.225806 | Q15: =H15-G15 -> 11.041667 | R15: =R16 -> 322.58065 | S15: =J15+K15+L15 -> 93 | T15: =R15-S15 -> 229.58065 | U15: =U16+N15 -> 1437.0968 | V15: =V16+O15 -> 203 | W15: =U15-V15 -> 1234.0968 | X15: =X16+R15 -> 8709.6774 | Y15: =Y16+S15 -> 1473 | Z15: =X15-Y15 -> 7236.6774 | AA15: =COS(ATAN(M15/S15)) -> 0.99855787
B16: 26 | C16: =C17+30 -> 255305 | D16: =D17+51 -> 510161 | E16: =E17+9 -> 168473 | F16: =C16+D16+E16 -> 933939 | G16: =(C17+D17+E17)+((S16/24)*7.5) -> 933877.12 | H16: =G16+((K16/12)*2.5) -> 933887.75 | I16: =I17+5 -> 298928 | J16: =C16-C17 -> 30 | K16: =D16-D17 -> 51 | L16: =E16-E17 -> 9 | M16: =I16-I17 -> 5 | N16: =N17 -> 53.225806 | O16: =L16 -> 9 | P16: =N16-O16 -> 44.225806 | Q16: =H16-G16 -> 10.625 | R16: =R17 -> 322.58065 | S16: =J16+K16+L16 -> 90 | T16: =R16-S16 -> 232.58065 | U16: =U17+N16 -> 1383.871 | V16: =V17+O16 -> 191 | W16: =U16-V16 -> 1192.871 | X16: =X17+R16 -> 8387.0968 | Y16: =Y17+S16 -> 1380 | Z16: =X16-Y16 -> 7007.0968 | AA16: =COS(ATAN(M16/S16)) -> 0.99846035
B17: 25 | C17: =C18+29 -> 255275 | D17: =D18+55 -> 510110 | E17: =E18+10 -> 168464 | F17: =C17+D17+E17 -> 933849 | G17: =(C18+D18+E18)+((S17/24)*7.5) -> 933784.38 | H17: =G17+((K17/12)*2.5) -> 933795.83 | I17: =I18+10 -> 298923 | J17: =C17-C18 -> 29 | K17: =D17-D18 -> 55 | L17: =E17-E18 -> 10 | M17: =I17-I18 -> 10 | N17: =N18 -> 53.225806 | O17: =L17 -> 10 | P17: =N17-O17 -> 43.225806 | Q17: =H17-G17 -> 11.458333 | R17: =R18 -> 322.58065 | S17: =J17+K17+L17 -> 94 | T17: =R17-S17 -> 228.58065 | U17: =U18+N17 -> 1330.6452 | V17: =V18+O17 -> 182 | W17: =U17-V17 -> 1148.6452 | X17: =X18+R17 -> 8064.5161 | Y17: =Y18+S17 -> 1290 | Z17: =X17-Y17 -> 6774.5161 | AA17: =COS(ATAN(M17/S17)) -> 0.99438891
B18: 24 | C18: =C19+24 -> 255246 | D18: =D19+53 -> 510055 | E18: =E19+13 -> 168454 | F18: =C18+D18+E18 -> 933755 | G18: =(C19+D19+E19)+((S18/24)*7.5) -> 933693.12 | H18: =G18+((K18/12)*2.5) -> 933704.17 | I18: =I19+8 -> 298913 | J18: =C18-C19 -> 24 | K18: =D18-D19 -> 53 | L18: =E18-E19 -> 13 | M18: =I18-I19 -> 8 | N18: =N19 -> 53.225806 | O18: =L18 -> 13 | P18: =N18-O18 -> 40.225806 | Q18: =H18-G18 -> 11.041667 | R18: =R19 -> 322.58065 | S18: =J18+K18+L18 -> 90 | T18: =R18-S18 -> 232.58065 | U18: =U19+N18 -> 1277.4194 | V18: =V19+O18 -> 172 | W18: =U18-V18 -> 1105.4194 | X18: =X19+R18 -> 7741.9355 | Y18: =Y19+S18 -> 1196 | Z18: =X18-Y18 -> 6545.9355 | AA18: =COS(ATAN(M18/S18)) -> 0.99607264
B19: 23 | C19: =C20+27 -> 255222 | D19: =D20+49 -> 510002 | E19: =E20+11 -> 168441 | F19: =C19+D19+E19 -> 933665 | G19: =(C20+D20+E20)+((S19/24)*7.5) -> 933605.19 | H19: =G19+((K19/12)*2.5) -> 933615.4 | I19: =I20+8 -> 298905 | J19: =C19-C20 -> 27 | K19: =D19-D20 -> 49 | L19: =E19-E20 -> 11 | M19: =I19-I20 -> 8 | N19: =N20 -> 53.225806 | O19: =L19 -> 11 | P19: =N19-O19 -> 42.225806 | Q19: =H19-G19 -> 10.208333 | R19: =R20 -> 322.58065 | S19: =J19+K19+L19 -> 87 | T19: =R19-S19 -> 235.58065 | U19: =U20+N19 -> 1224.1935 | V19: =V20+O19 -> 159 | W19: =U19-V19 -> 1065.1935 | X19: =X20+R19 -> 7419.3548 | Y19: =Y20+S19 -> 1106 | Z19: =X19-Y19 -> 6313.3548 | AA19: =COS(ATAN(M19/S19)) -> 0.99579885
B20: 22 | C20: 255195 | D20: 509953 | E20: 168430 | F20: =C20+D20+E20 -> 933578 | G20: =(C21+D21+E21)+((S20/24)*7.5) -> 933538.81 | H20: =G20+((K20/12)*2.5) -> 933543.4 | I20: 298897 | J20: =C20-C21 -> 25 | K20: =D20-D21 -> 22 | L20: =E20-E21 -> 10 | M20: =I20-I21 -> 8 | N20: =N21 -> 53.225806 | O20: =L20 -> 10 | P20: =N20-O20 -> 43.225806 | Q20: =H20-G20 -> 4.5833333 | R20: =R21 -> 322.58065 | S20: =J20+K20+L20 -> 57 | T20: =R20-S20 -> 265.58065 | U20: =U21+N20 -> 1170.9677 | V20: =V21+O20 -> 148 | W20: =U20-V20 -> 1022.9677 | X20: =X21+R20 -> 7096.7742 | Y20: =Y21+S20 -> 1019 | Z20: =X20-Y20 -> 6077.7742 | AA20: =COS(ATAN(M20/S20)) -> 0.99029398
B21: 21 | C21: =C22+21 -> 255170 | D21: =D22+25 -> 509931 | E21: =E22+9 -> 168420 | F21: =C21+D21+E21 -> 933521 | G21: =(C22+D22+E22)+((S21/24)*7.5) -> 933483.19 | H21: =G21+((K21/12)*2.5) -> 933488.4 | I21: =I22+5 -> 298889 | J21: =C21-C22 -> 21 | K21: =D21-D22 -> 25 | L21: =E21-E22 -> 9 | M21: =I21-I22 -> 5 | N21: =N22 -> 53.225806 | O21: =L21 -> 9 | P21: =N21-O21 -> 44.225806 | Q21: =H21-G21 -> 5.2083333 | R21: =R22 -> 322.58065 | S21: =J21+K21+L21 -> 55 | T21: =R21-S21 -> 267.58065 | U21: =U22+N21 -> 1117.7419 | V21: =V22+O21 -> 138 | W21: =U21-V21 -> 979.74194 | X21: =X22+R21 -> 6774.1935 | Y21: =Y22+S21 -> 962 | Z21: =X21-Y21 -> 5812.1935 | AA21: =COS(ATAN(M21/S21)) -> 0.99589321
B22: 20 | C22: =C23+20 -> 255149 | D22: =D23+27 -> 509906 | E22: =E23+10 -> 168411 | F22: =C22+D22+E22 -> 933466 | G22: =(C23+D23+E23)+((S22/24)*7.5) -> 933426.81 | H22: =G22+((K22/12)*2.5) -> 933432.44 | I22: =I23+6 -> 298884 | J22: =C22-C23 -> 20 | K22: =D22-D23 -> 27 | L22: =E22-E23 -> 10 | M22: =I22-I23 -> 6 | N22: =N23 -> 53.225806 | O22: =L22 -> 10 | P22: =N22-O22 -> 43.225806 | Q22: =H22-G22 -> 5.625 | R22: =R23 -> 322.58065 | S22: =J22+K22+L22 -> 57 | T22: =R22-S22 -> 265.58065 | U22: =U23+N22 -> 1064.5161 | V22: =V23+O22 -> 129 | W22: =U22-V22 -> 935.51613 | X22: =X23+R22 -> 6451.6129 | Y22: =Y23+S22 -> 907 | Z22: =X22-Y22 -> 5544.6129 | AA22: =COS(ATAN(M22/S22)) -> 0.99450545
B23: 19 | C23: =C24+21 -> 255129 | D23: =D24+24 -> 509879 | E23: =E24+9 -> 168401 | F23: =C23+D23+E23 -> 933409 | G23: =(C24+D24+E24)+((S23/24)*7.5) -> 933371.88 | H23: =G23+((K23/12)*2.5) -> 933376.88 | I23: =I24+5 -> 298878 | J23: =C23-C24 -> 21 | K23: =D23-D24 -> 24 | L23: =E23-E24 -> 9 | M23: =I23-I24 -> 5 | N23: =N24 -> 53.225806 | O23: =L23 -> 9 | P23: =N23-O23 -> 44.225806 | Q23: 9 | R23: =R24 -> 322.58065 | S23: =J23+K23+L23 -> 54 | T23: =R23-S23 -> 268.58065 | U23: =U24+N23 -> 1011.2903 | V23: =V24+O23 -> 119 | W23: =U23-V23 -> 892.29032 | X23: =X24+R23 -> 6129.0323 | Y23: =Y24+S23 -> 850 | Z23: =X23-Y23 -> 5279.0323 | AA23: =COS(ATAN(M23/S23)) -> 0.99574067
B24: 18 | C24: =C25+23 -> 255108 | D24: =D25+26 -> 509855 | E24: =E25+8 -> 168392 | F24: =C24+D24+E24 -> 933355 | G24: =(C25+D25+E25)+((S24/24)*7.5) -> 933315.81 | H24: =G24+((K24/12)*2.5) -> 933321.23 | I24: =I25+4 -> 298873 | J24: =C24-C25 -> 23 | K24: =D24-D25 -> 26 | L24: =E24-E25 -> 8 | M24: =I24-I25 -> 4 | N24: =N25 -> 53.225806 | O24: =L24 -> 8 | P24: =N24-O24 -> 45.225806 | Q24: 7 | R24: =R25 -> 322.58065 | S24: =J24+K24+L24 -> 57 | T24: =R24-S24 -> 265.58065 | U24: =U25+N24 -> 958.06452 | V24: =V25+O24 -> 110 | W24: =U24-V24 -> 848.06452 | X24: =X25+R24 -> 5806.4516 | Y24: =Y25+S24 -> 796 | Z24: =X24-Y24 -> 5010.4516 | AA24: =COS(ATAN(M24/S24)) -> 0.99754676
B25: 17 | C25: =C26+19 -> 255085 | D25: =D26+23 -> 509829 | E25: =E26+11 -> 168384 | F25: =C25+D25+E25 -> 933298 | G25: =(C26+D26+E26)+((S25/24)*7.5) -> 933261.56 | H25: =G25+((K25/12)*2.5) -> 933266.35 | I25: =I26+5 -> 298869 | J25: =C25-C26 -> 19 | K25: =D25-D26 -> 23 | L25: =E25-E26 -> 11 | M25: =I25-I26 -> 5 | N25: =N26 -> 53.225806 | O25: =L25 -> 11 | P25: =N25-O25 -> 42.225806 | Q25: =H25-G25 -> 4.7916667 | R25: =R26 -> 322.58065 | S25: =J25+K25+L25 -> 53 | T25: =R25-S25 -> 269.58065 | U25: =U26+N25 -> 904.83871 | V25: =V26+O25 -> 102 | W25: =U25-V25 -> 802.83871 | X25: =X26+R25 -> 5483.871 | Y25: =Y26+S25 -> 739 | Z25: =X25-Y25 -> 4744.871 | AA25: =COS(ATAN(M25/S25)) -> 0.9955795
B26: 16 | C26: =C27+22 -> 255066 | D26: =D27+25 -> 509806 | E26: =E27+7 -> 168373 | F26: =C26+D26+E26 -> 933245 | G26: =(C27+D27+E27)+((S26/24)*7.5) -> 933207.88 | H26: =G26+((K26/12)*2.5) -> 933213.08 | I26: =I27+7 -> 298864 | J26: =C26-C27 -> 22 | K26: =D26-D27 -> 25 | L26: =E26-E27 -> 7 | M26: =I26-I27 -> 7 | N26: =N27 -> 53.225806 | O26: =L26 -> 7 | P26: =N26-O26 -> 46.225806 | Q26: =H26-G26 -> 5.2083333 | R26: =R27 -> 322.58065 | S26: =J26+K26+L26 -> 54 | T26: =R26-S26 -> 268.58065 | U26: =U27+N26 -> 851.6129 | V26: =V27+O26 -> 91 | W26: =U26-V26 -> 760.6129 | X26: =X27+R26 -> 5161.2903 | Y26: =Y27+S26 -> 686 | Z26: =X26-Y26 -> 4475.2903 | AA26: =COS(ATAN(M26/S26)) -> 0.99170251
B27: 15 | C27: =C28+20 -> 255044 | D27: =D28+29 -> 509781 | E27: =E28+9 -> 168366 | F27: =C27+D27+E27 -> 933191 | G27: =(C28+D28+E28)+((S27/24)*7.5) -> 933151.12 | H27: =G27+((K27/12)*2.5) -> 933157.17 | I27: =I28+5 -> 298857 | J27: =C27-C28 -> 20 | K27: =D27-D28 -> 29 | L27: =E27-E28 -> 9 | M27: =I27-I28 -> 5 | N27: =N28 -> 53.225806 | O27: =L27 -> 9 | P27: =N27-O27 -> 44.225806 | Q27: =H27-G27 -> 6.0416667 | R27: =R28 -> 322.58065 | S27: =J27+K27+L27 -> 58 | T27: =R27-S27 -> 264.58065 | U27: =U28+N27 -> 798.3871 | V27: =V28+O27 -> 84 | W27: =U27-V27 -> 714.3871 | X27: =X28+R27 -> 4838.7097 | Y27: =Y28+S27 -> 632 | Z27: =X27-Y27 -> 4206.7097 | AA27: =COS(ATAN(M27/S27)) -> 0.99630477
B28: 14 | C28: =C29+11 -> 255024 | D28: =D29+31 -> 509752 | E28: =E29+8 -> 168357 | F28: =C28+D28+E28 -> 933133 | G28: =(C29+D29+E29)+((S28/24)*7.5) -> 933098.62 | H28: =G28+((K28/12)*2.5) -> 933105.08 | I28: =I29+12 -> 298852 | J28: =C28-C29 -> 11 | K28: =D28-D29 -> 31 | L28: =E28-E29 -> 8 | M28: =I28-I29 -> 12 | N28: =N29 -> 53.225806 | O28: =L28 -> 8 | P28: =N28-O28 -> 45.225806 | Q28: =H28-G28 -> 6.4583333 | R28: =R29 -> 322.58065 | S28: =J28+K28+L28 -> 50 | T28: =R28-S28 -> 272.58065 | U28: =U29+N28 -> 745.16129 | V28: =V29+O28 -> 75 | W28: =U28-V28 -> 670.16129 | X28: =X29+R28 -> 4516.129 | Y28: =Y29+S28 -> 574 | Z28: =X28-Y28 -> 3942.129 | AA28: =COS(ATAN(M28/S28)) -> 0.9723873
